Workbook

Sheet Character
A1: Character
A3: Identity & Core Stats
A4: Name | D4: Species | G4: Background | J4: Alignment
A5: Inspiration | D5: Speed | G5: Proficiency Bonus | J5: Total Level | K5: =SUM(C11:C14) -> 0
A6: Spellcasting Ability | D6: Spell Atk Misc | G6: Spell DC Misc | J6: Initiative Misc
A7: HP Current | D7: HP Max | G7: Temp HP | J7: Initiative Total | K7: =J12+K6 -> 0
A9: Classes | H9: Ability Scores
A10: Slot | B10: Class | C10: Level | D10: Subclass | E10: Hit Die | F10: Casting Stat | H10: Ability | I10: Score | J10: Mod
A11: 1 | E11: {=IFERROR(INDEX(Data!$E$5:$E$18,MATCH(B11,Data!$D$5:$D$18,0)),"")} | F11: {=IFERROR(INDEX(Data!$F$5:$F$18,MATCH(B11,Data!$D$5:$D$18,0)),"")} | H11: STR | J11: =IF(I11="","",INT((I11-10)/2))
A12: 2 | E12: {=IFERROR(INDEX(Data!$E$5:$E$18,MATCH(B12,Data!$D$5:$D$18,0)),"")} | F12: {=IFERROR(INDEX(Data!$F$5:$F$18,MATCH(B12,Data!$D$5:$D$18,0)),"")} | H12: DEX | J12: =IF(I12="","",INT((I12-10)/2))
A13: 3 | E13: {=IFERROR(INDEX(Data!$E$5:$E$18,MATCH(B13,Data!$D$5:$D$18,0)),"")} | F13: {=IFERROR(INDEX(Data!$F$5:$F$18,MATCH(B13,Data!$D$5:$D$18,0)),"")} | H13: CON | J13: =IF(I13="","",INT((I13-10)/2))
A14: 4 | E14: {=IFERROR(INDEX(Data!$E$5:$E$18,MATCH(B14,Data!$D$5:$D$18,0)),"")} | F14: {=IFERROR(INDEX(Data!$F$5:$F$18,MATCH(B14,Data!$D$5:$D$18,0)),"")} | H14: INT | J14: =IF(I14="","",INT((I14-10)/2))
H15: WIS | J15: =IF(I15="","",INT((I15-10)/2))
H16: CHA | J16: =IF(I16="","",INT((I16-10)/2))
A17: Saving Throws | G17: Skills
A18: Save | B18: Stat | C18: Prof | D18: Misc | E18: Total | G18: Skill | H18: Stat | I18: Prof | J18: Misc | K18: Total
A19: STR Save | B19: STR | E19: {=IF(B19="","",$J$11+INT($H$5*IFERROR(INDEX(Data!$B$5:$B$8,MATCH(C19,Data!$A$5:$A$8,0)),0))+D19)} -> 0 | G19: Acrobatics | H19: DEX | K19: {=IF(H19="","",$J$12+INT($H$5*IFERROR(INDEX(Data!$B$5:$B$8,MATCH(I19,Data!$A$5:$A$8,0)),0))+J19)} -> 0
A20: DEX Save | B20: DEX | E20: {=IF(B20="","",$J$12+INT($H$5*IFERROR(INDEX(Data!$B$5:$B$8,MATCH(C20,Data!$A$5:$A$8,0)),0))+D20)} -> 0 | G20: Animal Handling | H20: WIS | K20: {=IF(H20="","",$J$15+INT($H$5*IFERROR(INDEX(Data!$B$5:$B$8,MATCH(I20,Data!$A$5:$A$8,0)),0))+J20)} -> 0
A21: CON Save | B21: CON | E21: {=IF(B21="","",$J$13+INT($H$5*IFERROR(INDEX(Data!$B$5:$B$8,MATCH(C21,Data!$A$5:$A$8,0)),0))+D21)} -> 0 | G21: Arcana | H21: INT | K21: {=IF(H21="","",$J$14+INT($H$5*IFERROR(INDEX(Data!$B$5:$B$8,MATCH(I21,Data!$A$5:$A$8,0)),0))+J21)} -> 0
A22: INT Save | B22: INT | E22: {=IF(B22="","",$J$14+INT($H$5*IFERROR(INDEX(Data!$B$5:$B$8,MATCH(C22,Data!$A$5:$A$8,0)),0))+D22)} -> 0 | G22: Athletics | H22: STR | K22: {=IF(H22="","",$J$11+INT($H$5*IFERROR(INDEX(Data!$B$5:$B$8,MATCH(I22,Data!$A$5:$A$8,0)),0))+J22)} -> 0
A23: WIS Save | B23: WIS | E23: {=IF(B23="","",$J$15+INT($H$5*IFERROR(INDEX(Data!$B$5:$B$8,MATCH(C23,Data!$A$5:$A$8,0)),0))+D23)} -> 0 | G23: Deception | H23: CHA | K23: {=IF(H23="","",$J$16+INT($H$5*IFERROR(INDEX(Data!$B$5:$B$8,MATCH(I23,Data!$A$5:$A$8,0)),0))+J23)} -> 0
A24: CHA Save | B24: CHA | E24: {=IF(B24="","",$J$16+INT($H$5*IFERROR(INDEX(Data!$B$5:$B$8,MATCH(C24,Data!$A$5:$A$8,0)),0))+D24)} -> 0 | G24: History | H24: INT | K24: {=IF(H24="","",$J$14+INT($H$5*IFERROR(INDEX(Data!$B$5:$B$8,MATCH(I24,Data!$A$5:$A$8,0)),0))+J24)} -> 0
G25: Insight | H25: WIS | K25: {=IF(H25="","",$J$15+INT($H$5*IFERROR(INDEX(Data!$B$5:$B$8,MATCH(I25,Data!$A$5:$A$8,0)),0))+J25)} -> 0
G26: Intimidation | H26: CHA | K26: {=IF(H26="","",$J$16+INT($H$5*IFERROR(INDEX(Data!$B$5:$B$8,MATCH(I26,Data!$A$5:$A$8,0)),0))+J26)} -> 0
A27: Passives | D27: Spell Summary | G27: Investigation | H27: INT | K27: {=IF(H27="","",$J$14+INT($H$5*IFERROR(INDEX(Data!$B$5:$B$8,MATCH(I27,Data!$A$5:$A$8,0)),0))+J27)} -> 0
A28: Field | B28: Value | D28: Field | E28: Value | G28: Medicine | H28: WIS | K28: {=IF(H28="","",$J$15+INT($H$5*IFERROR(INDEX(Data!$B$5:$B$8,MATCH(I28,Data!$A$5:$A$8,0)),0))+J28)} -> 0
A29: Passive Perception | B29: =10+K30 -> 10 | D29: Spellcasting Mod | E29: =IF(B6="None","",IF(B6="STR",$J$11,IF(B6="DEX",$J$12,IF(B6="CON",$J$13,IF(B6="INT",$J$14,IF(B6="WIS",$J$15,IF(B6="CHA",$J$16,""))))))) | G29: Nature | H29: INT | K29: {=IF(H29="","",$J$14+INT($H$5*IFERROR(INDEX(Data!$B$5:$B$8,MATCH(I29,Data!$A$5:$A$8,0)),0))+J29)} -> 0
A30: Passive Insight | B30: =10+K25 -> 10 | D30: Spell Attack | E30: =IF(E29="","",E29+$H$5+E6) | G30: Perception | H30: WIS | K30: {=IF(H30="","",$J$15+INT($H$5*IFERROR(INDEX(Data!$B$5:$B$8,MATCH(I30,Data!$A$5:$A$8,0)),0))+J30)} -> 0
A31: Passive Investigation | B31: =10+K27 -> 10 | D31: Spell Save DC | E31: =IF(E29="","",8+E29+$H$5+H6) | G31: Performance | H31: CHA | K31: {=IF(H31="","",$J$16+INT($H$5*IFERROR(INDEX(Data!$B$5:$B$8,MATCH(I31,Data!$A$5:$A$8,0)),0))+J31)} -> 0
G32: Persuasion | H32: CHA | K32: {=IF(H32="","",$J$16+INT($H$5*IFERROR(INDEX(Data!$B$5:$B$8,MATCH(I32,Data!$A$5:$A$8,0)),0))+J32)} -> 0
G33: Religion | H33: INT | K33: {=IF(H33="","",$J$14+INT($H$5*IFERROR(INDEX(Data!$B$5:$B$8,MATCH(I33,Data!$A$5:$A$8,0)),0))+J33)} -> 0
G34: Sleight of Hand | H34: DEX | K34: {=IF(H34="","",$J$12+INT($H$5*IFERROR(INDEX(Data!$B$5:$B$8,MATCH(I34,Data!$A$5:$A$8,0)),0))+J34)} -> 0
G35: Stealth | H35: DEX | K35: {=IF(H35="","",$J$12+INT($H$5*IFERROR(INDEX(Data!$B$5:$B$8,MATCH(I35,Data!$A$5:$A$8,0)),0))+J35)} -> 0
G36: Survival | H36: WIS | K36: {=IF(H36="","",$J$15+INT($H$5*IFERROR(INDEX(Data!$B$5:$B$8,MATCH(I36,Data!$A$5:$A$8,0)),0))+J36)} -> 0

Sheet Combat
A1: Combat
A3: Defense
A4: Armor
A5: Shield
A6: Armor Misc AC
A7: Unarmored Base | B7: 10
A8: DEX Cap Override | D8: TWF Style?
A9: Final AC | B9: {=IF(B4="","",IFERROR(INDEX(Data!$R$5:$R$16,MATCH(B4,Data!$Q$5:$Q$16,0)),B7)+MIN(Character!$J$12,IF(B8="",IFERROR(INDEX(Data!$S$5:$S$16,MATCH(B4,Data!$Q$5:$Q$16,0)),99),B8))+IFERROR(INDEX(Data!$Y$5:$Y$6,MATCH(B5,Data!$X$5:$X$6,0)),0)+B6)} | D9: Dual Wielder?
A11: Weapons & Attacks
A12: Equipped | B12: Favorite | C12: Hand | D12: Base Weapon | E12: Display Name | F12: Atk Stat | G12: Dmg Stat | H12: Prof | I12: Magic | J12: Atk Misc | K12: Dmg Misc | L12: Custom Atk | M12: Custom Dmg | N12: Dmg Override | O12: Type Override | P12: Range Override | Q12: Notes | R12: Final Name | S12: Atk Bonus | T12: Damage Die | U12: Dmg Mod | V12: Damage Formula | W12: Damage Type | X12: Range | Y12: Offhand Rule Note | Z12: Base Damage | AA12: Alt Damage | AB12: Base Type | AC12: Base Range | AD12: Finesse | AE12: Light | AF12: Two-Handed | AG12: Versatile | AH12: Thrown | AI12: Ranged | AJ12: Ammo | AK12: Loading | AL12: Reach
R13: =IF(E13<>"",E13,D13) | S13: {=IF(D13="","",IF(F13="None",0,IF(F13="Custom",L13,IF(F13="STR",Character!$J$11,IF(F13="DEX",Character!$J$12,IF(F13="Finesse",MAX(Character!$J$11,Character!$J$12),IF(F13="Auto",IF(AK13="TRUE",Character!$J$12,IF(AD13="TRUE",MAX(Character!$J$11,Character!$J$12),Character!$J$11)),0))))))+INT(Character!$H$5*IFERROR(INDEX(Data!$B$5:$B$8,MATCH(H13,Data!$A$5:$A$8,0)),0))+I13+J13)} | T13: =IF(D13="","",IF(N13<>"",N13,IF(AND(C13="Both",AG13="TRUE",AA13<>""),AA13,Z13))) | U13: =IF(D13="","",IF(G13="None",0,IF(G13="Custom",M13,IF(G13="STR",Character!$J$11,IF(G13="DEX",Character!$J$12,IF(G13="Finesse",MAX(Character!$J$11,Character!$J$12),IF(G13="Auto",IF(AK13="TRUE",Character!$J$12,IF(AD13="TRUE",MAX(Character!$J$11,Character!$J$12),Character!$J$11)),0))))))+I13+K13) | V13: =IF(T13="","",T13&IF(U13>0,"+"&U13,IF(U13<0,U13,""))) | W13: =IF(O13<>"",O13,AB13) | X13: =IF(P13<>"",P13,AC13) | Y13: =IF(C13<>"Off","",IF(OR(AE13="TRUE",$E$9="TRUE"),"Bonus Action; no ability mod to damage unless TWF Style is TRUE","Check rules: off-hand usually needs a Light weapon or Dual Wielder")) | Z13: {=IFERROR(INDEX(Data!$AC$5:$AC$24,MATCH(D13,Data!$AA$5:$AA$24,0)),"")} | AA13: {=IFERROR(INDEX(Data!$AF$5:$AF$24,MATCH(D13,Data!$AA$5:$AA$24,0)),"")} | AB13: {=IFERROR(INDEX(Data!$AD$5:$AD$24,MATCH(D13,Data!$AA$5:$AA$24,0)),"")} | AC13: {=IFERROR(INDEX(Data!$AE$5:$AE$24,MATCH(D13,Data!$AA$5:$AA$24,0)),"")} | AD13: {=IFERROR(INDEX(Data!$AG$5:$AG$24,MATCH(D13,Data!$AA$5:$AA$24,0)),"FALSE")} -> FALSE | AE13: {=IFERROR(INDEX(Data!$AH$5:$AH$24,MATCH(D13,Data!$AA$5:$AA$24,0)),"FALSE")} -> FALSE | AF13: {=IFERROR(INDEX(Data!$AI$5:$AI$24,MATCH(D13,Data!$AA$5:$AA$24,0)),"FALSE")} -> FALSE | AG13: {=IFERROR(INDEX(Data!$AJ$5:$AJ$24,MATCH(D13,Data!$AA$5:$AA$24,0)),"FALSE")} -> FALSE | AH13: {=IFERROR(INDEX(Data!$AK$5:$AK$24,MATCH(D13,Data!$AA$5:$AA$24,0)),"FALSE")} -> FALSE | AI13: {=IFERROR(INDEX(Data!$AL$5:$AL$24,MATCH(D13,Data!$AA$5:$AA$24,0)),"FALSE")} -> FALSE | AJ13: {=IFERROR(INDEX(Data!$AM$5:$AM$24,MATCH(D13,Data!$AA$5:$AA$24,0)),"FALSE")} -> FALSE | AK13: {=IFERROR(INDEX(Data!$AN$5:$AN$24,MATCH(D13,Data!$AA$5:$AA$24,0)),"FALSE")} -> FALSE | AL13: {=IFERROR(INDEX(Data!$AO$5:$AO$24,MATCH(D13,Data!$AA$5:$AA$24,0)),"FALSE")} -> FALSE
R14: =IF(E14<>"",E14,D14) | S14: {=IF(D14="","",IF(F14="None",0,IF(F14="Custom",L14,IF(F14="STR",Character!$J$11,IF(F14="DEX",Character!$J$12,IF(F14="Finesse",MAX(Character!$J$11,Character!$J$12),IF(F14="Auto",IF(AK14="TRUE",Character!$J$12,IF(AD14="TRUE",MAX(Character!$J$11,Character!$J$12),Character!$J$11)),0))))))+INT(Character!$H$5*IFERROR(INDEX(Data!$B$5:$B$8,MATCH(H14,Data!$A$5:$A$8,0)),0))+I14+J14)} | T14: =IF(D14="","",IF(N14<>"",N14,IF(AND(C14="Both",AG14="TRUE",AA14<>""),AA14,Z14))) | U14: =IF(D14="","",IF(G14="None",0,IF(G14="Custom",M14,IF(G14="STR",Character!$J$11,IF(G14="DEX",Character!$J$12,IF(G14="Finesse",MAX(Character!$J$11,Character!$J$12),IF(G14="Auto",IF(AK14="TRUE",Character!$J$12,IF(AD14="TRUE",MAX(Character!$J$11,Character!$J$12),Character!$J$11)),0))))))+I14+K14) | V14: =IF(T14="","",T14&IF(U14>0,"+"&U14,IF(U14<0,U14,""))) | W14: =IF(O14<>"",O14,AB14) | X14: =IF(P14<>"",P14,AC14) | Y14: =IF(C14<>"Off","",IF(OR(AE14="TRUE",$E$9="TRUE"),"Bonus Action; no ability mod to damage unless TWF Style is TRUE","Check rules: off-hand usually needs a Light weapon or Dual Wielder")) | Z14: {=IFERROR(INDEX(Data!$AC$5:$AC$24,MATCH(D14,Data!$AA$5:$AA$24,0)),"")} | AA14: {=IFERROR(INDEX(Data!$AF$5:$AF$24,MATCH(D14,Data!$AA$5:$AA$24,0)),"")} | AB14: {=IFERROR(INDEX(Data!$AD$5:$AD$24,MATCH(D14,Data!$AA$5:$AA$24,0)),"")} | AC14: {=IFERROR(INDEX(Data!$AE$5:$AE$24,MATCH(D14,Data!$AA$5:$AA$24,0)),"")} | AD14: {=IFERROR(INDEX(Data!$AG$5:$AG$24,MATCH(D14,Data!$AA$5:$AA$24,0)),"FALSE")} -> FALSE | AE14: {=IFERROR(INDEX(Data!$AH$5:$AH$24,MATCH(D14,Data!$AA$5:$AA$24,0)),"FALSE")} -> FALSE | AF14: {=IFERROR(INDEX(Data!$AI$5:$AI$24,MATCH(D14,Data!$AA$5:$AA$24,0)),"FALSE")} -> FALSE | AG14: {=IFERROR(INDEX(Data!$AJ$5:$AJ$24,MATCH(D14,Data!$AA$5:$AA$24,0)),"FALSE")} -> FALSE | AH14: {=IFERROR(INDEX(Data!$AK$5:$AK$24,MATCH(D14,Data!$AA$5:$AA$24,0)),"FALSE")} -> FALSE | AI14: {=IFERROR(INDEX(Data!$AL$5:$AL$24,MATCH(D14,Data!$AA$5:$AA$24,0)),"FALSE")} -> FALSE | AJ14: {=IFERROR(INDEX(Data!$AM$5:$AM$24,MATCH(D14,Data!$AA$5:$AA$24,0)),"FALSE")} -> FALSE | AK14: {=IFERROR(INDEX(Data!$AN$5:$AN$24,MATCH(D14,Data!$AA$5:$AA$24,0)),"FALSE")} -> FALSE | AL14: {=IFERROR(INDEX(Data!$AO$5:$AO$24,MATCH(D14,Data!$AA$5:$AA$24,0)),"FALSE")} -> FALSE
R15: =IF(E15<>"",E15,D15) | S15: {=IF(D15="","",IF(F15="None",0,IF(F15="Custom",L15,IF(F15="STR",Character!$J$11,IF(F15="DEX",Character!$J$12,IF(F15="Finesse",MAX(Character!$J$11,Character!$J$12),IF(F15="Auto",IF(AK15="TRUE",Character!$J$12,IF(AD15="TRUE",MAX(Character!$J$11,Character!$J$12),Character!$J$11)),0))))))+INT(Character!$H$5*IFERROR(INDEX(Data!$B$5:$B$8,MATCH(H15,Data!$A$5:$A$8,0)),0))+I15+J15)} | T15: =IF(D15="","",IF(N15<>"",N15,IF(AND(C15="Both",AG15="TRUE",AA15<>""),AA15,Z15))) | U15: =IF(D15="","",IF(G15="None",0,IF(G15="Custom",M15,IF(G15="STR",Character!$J$11,IF(G15="DEX",Character!$J$12,IF(G15="Finesse",MAX(Character!$J$11,Character!$J$12),IF(G15="Auto",IF(AK15="TRUE",Character!$J$12,IF(AD15="TRUE",MAX(Character!$J$11,Character!$J$12),Character!$J$11)),0))))))+I15+K15) | V15: =IF(T15="","",T15&IF(U15>0,"+"&U15,IF(U15<0,U15,""))) | W15: =IF(O15<>"",O15,AB15) | X15: =IF(P15<>"",P15,AC15) | Y15: =IF(C15<>"Off","",IF(OR(AE15="TRUE",$E$9="TRUE"),"Bonus Action; no ability mod to damage unless TWF Style is TRUE","Check rules: off-hand usually needs a Light weapon or Dual Wielder")) | Z15: {=IFERROR(INDEX(Data!$AC$5:$AC$24,MATCH(D15,Data!$AA$5:$AA$24,0)),"")} | AA15: {=IFERROR(INDEX(Data!$AF$5:$AF$24,MATCH(D15,Data!$AA$5:$AA$24,0)),"")} | AB15: {=IFERROR(INDEX(Data!$AD$5:$AD$24,MATCH(D15,Data!$AA$5:$AA$24,0)),"")} | AC15: {=IFERROR(INDEX(Data!$AE$5:$AE$24,MATCH(D15,Data!$AA$5:$AA$24,0)),"")} | AD15: {=IFERROR(INDEX(Data!$AG$5:$AG$24,MATCH(D15,Data!$AA$5:$AA$24,0)),"FALSE")} -> FALSE | AE15: {=IFERROR(INDEX(Data!$AH$5:$AH$24,MATCH(D15,Data!$AA$5:$AA$24,0)),"FALSE")} -> FALSE | AF15: {=IFERROR(INDEX(Data!$AI$5:$AI$24,MATCH(D15,Data!$AA$5:$AA$24,0)),"FALSE")} -> FALSE | AG15: {=IFERROR(INDEX(Data!$AJ$5:$AJ$24,MATCH(D15,Data!$AA$5:$AA$24,0)),"FALSE")} -> FALSE | AH15: {=IFERROR(INDEX(Data!$AK$5:$AK$24,MATCH(D15,Data!$AA$5:$AA$24,0)),"FALSE")} -> FALSE | AI15: {=IFERROR(INDEX(Data!$AL$5:$AL$24,MATCH(D15,Data!$AA$5:$AA$24,0)),"FALSE")} -> FALSE | AJ15: {=IFERROR(INDEX(Data!$AM$5:$AM$24,MATCH(D15,Data!$AA$5:$AA$24,0)),"FALSE")} -> FALSE | AK15: {=IFERROR(INDEX(Data!$AN$5:$AN$24,MATCH(D15,Data!$AA$5:$AA$24,0)),"FALSE")} -> FALSE | AL15: {=IFERROR(INDEX(Data!$AO$5:$AO$24,MATCH(D15,Data!$AA$5:$AA$24,0)),"FALSE")} -> FALSE
R16: =IF(E16<>"",E16,D16) | S16: {=IF(D16="","",IF(F16="None",0,IF(F16="Custom",L16,IF(F16="STR",Character!$J$11,IF(F16="DEX",Character!$J$12,IF(F16="Finesse",MAX(Character!$J$11,Character!$J$12),IF(F16="Auto",IF(AK16="TRUE",Character!$J$12,IF(AD16="TRUE",MAX(Character!$J$11,Character!$J$12),Character!$J$11)),0))))))+INT(Character!$H$5*IFERROR(INDEX(Data!$B$5:$B$8,MATCH(H16,Data!$A$5:$A$8,0)),0))+I16+J16)} | T16: =IF(D16="","",IF(N16<>"",N16,IF(AND(C16="Both",AG16="TRUE",AA16<>""),AA16,Z16))) | U16: =IF(D16="","",IF(G16="None",0,IF(G16="Custom",M16,IF(G16="STR",Character!$J$11,IF(G16="DEX",Character!$J$12,IF(G16="Finesse",MAX(Character!$J$11,Character!$J$12),IF(G16="Auto",IF(AK16="TRUE",Character!$J$12,IF(AD16="TRUE",MAX(Character!$J$11,Character!$J$12),Character!$J$11)),0))))))+I16+K16) | V16: =IF(T16="","",T16&IF(U16>0,"+"&U16,IF(U16<0,U16,""))) | W16: =IF(O16<>"",O16,AB16) | X16: =IF(P16<>"",P16,AC16) | Y16: =IF(C16<>"Off","",IF(OR(AE16="TRUE",$E$9="TRUE"),"Bonus Action; no ability mod to damage unless TWF Style is TRUE","Check rules: off-hand usually needs a Light weapon or Dual Wielder")) | Z16: {=IFERROR(INDEX(Data!$AC$5:$AC$24,MATCH(D16,Data!$AA$5:$AA$24,0)),"")} | AA16: {=IFERROR(INDEX(Data!$AF$5:$AF$24,MATCH(D16,Data!$AA$5:$AA$24,0)),"")} | AB16: {=IFERROR(INDEX(Data!$AD$5:$AD$24,MATCH(D16,Data!$AA$5:$AA$24,0)),"")} | AC16: {=IFERROR(INDEX(Data!$AE$5:$AE$24,MATCH(D16,Data!$AA$5:$AA$24,0)),"")} | AD16: {=IFERROR(INDEX(Data!$AG$5:$AG$24,MATCH(D16,Data!$AA$5:$AA$24,0)),"FALSE")} -> FALSE | AE16: {=IFERROR(INDEX(Data!$AH$5:$AH$24,MATCH(D16,Data!$AA$5:$AA$24,0)),"FALSE")} -> FALSE | AF16: {=IFERROR(INDEX(Data!$AI$5:$AI$24,MATCH(D16,Data!$AA$5:$AA$24,0)),"FALSE")} -> FALSE | AG16: {=IFERROR(INDEX(Data!$AJ$5:$AJ$24,MATCH(D16,Data!$AA$5:$AA$24,0)),"FALSE")} -> FALSE | AH16: {=IFERROR(INDEX(Data!$AK$5:$AK$24,MATCH(D16,Data!$AA$5:$AA$24,0)),"FALSE")} -> FALSE | AI16: {=IFERROR(INDEX(Data!$AL$5:$AL$24,MATCH(D16,Data!$AA$5:$AA$24,0)),"FALSE")} -> FALSE | AJ16: {=IFERROR(INDEX(Data!$AM$5:$AM$24,MATCH(D16,Data!$AA$5:$AA$24,0)),"FALSE")} -> FALSE | AK16: {=IFERROR(INDEX(Data!$AN$5:$AN$24,MATCH(D16,Data!$AA$5:$AA$24,0)),"FALSE")} -> FALSE | AL16: {=IFERROR(INDEX(Data!$AO$5:$AO$24,MATCH(D16,Data!$AA$5:$AA$24,0)),"FALSE")} -> FALSE
R17: =IF(E17<>"",E17,D17) | S17: {=IF(D17="","",IF(F17="None",0,IF(F17="Custom",L17,IF(F17="STR",Character!$J$11,IF(F17="DEX",Character!$J$12,IF(F17="Finesse",MAX(Character!$J$11,Character!$J$12),IF(F17="Auto",IF(AK17="TRUE",Character!$J$12,IF(AD17="TRUE",MAX(Character!$J$11,Character!$J$12),Character!$J$11)),0))))))+INT(Character!$H$5*IFERROR(INDEX(Data!$B$5:$B$8,MATCH(H17,Data!$A$5:$A$8,0)),0))+I17+J17)} | T17: =IF(D17="","",IF(N17<>"",N17,IF(AND(C17="Both",AG17="TRUE",AA17<>""),AA17,Z17))) | U17: =IF(D17="","",IF(G17="None",0,IF(G17="Custom",M17,IF(G17="STR",Character!$J$11,IF(G17="DEX",Character!$J$12,IF(G17="Finesse",MAX(Character!$J$11,Character!$J$12),IF(G17="Auto",IF(AK17="TRUE",Character!$J$12,IF(AD17="TRUE",MAX(Character!$J$11,Character!$J$12),Character!$J$11)),0))))))+I17+K17) | V17: =IF(T17="","",T17&IF(U17>0,"+"&U17,IF(U17<0,U17,""))) | W17: =IF(O17<>"",O17,AB17) | X17: =IF(P17<>"",P17,AC17) | Y17: =IF(C17<>"Off","",IF(OR(AE17="TRUE",$E$9="TRUE"),"Bonus Action; no ability mod to damage unless TWF Style is TRUE","Check rules: off-hand usually needs a Light weapon or Dual Wielder")) | Z17: {=IFERROR(INDEX(Data!$AC$5:$AC$24,MATCH(D17,Data!$AA$5:$AA$24,0)),"")} | AA17: {=IFERROR(INDEX(Data!$AF$5:$AF$24,MATCH(D17,Data!$AA$5:$AA$24,0)),"")} | AB17: {=IFERROR(INDEX(Data!$AD$5:$AD$24,MATCH(D17,Data!$AA$5:$AA$24,0)),"")} | AC17: {=IFERROR(INDEX(Data!$AE$5:$AE$24,MATCH(D17,Data!$AA$5:$AA$24,0)),"")} | AD17: {=IFERROR(INDEX(Data!$AG$5:$AG$24,MATCH(D17,Data!$AA$5:$AA$24,0)),"FALSE")} -> FALSE | AE17: {=IFERROR(INDEX(Data!$AH$5:$AH$24,MATCH(D17,Data!$AA$5:$AA$24,0)),"FALSE")} -> FALSE | AF17: {=IFERROR(INDEX(Data!$AI$5:$AI$24,MATCH(D17,Data!$AA$5:$AA$24,0)),"FALSE")} -> FALSE | AG17: {=IFERROR(INDEX(Data!$AJ$5:$AJ$24,MATCH(D17,Data!$AA$5:$AA$24,0)),"FALSE")} -> FALSE | AH17: {=IFERROR(INDEX(Data!$AK$5:$AK$24,MATCH(D17,Data!$AA$5:$AA$24,0)),"FALSE")} -> FALSE | AI17: {=IFERROR(INDEX(Data!$AL$5:$AL$24,MATCH(D17,Data!$AA$5:$AA$24,0)),"FALSE")} -> FALSE | AJ17: {=IFERROR(INDEX(Data!$AM$5:$AM$24,MATCH(D17,Data!$AA$5:$AA$24,0)),"FALSE")} -> FALSE | AK17: {=IFERROR(INDEX(Data!$AN$5:$AN$24,MATCH(D17,Data!$AA$5:$AA$24,0)),"FALSE")} -> FALSE | AL17: {=IFERROR(INDEX(Data!$AO$5:$AO$24,MATCH(D17,Data!$AA$5:$AA$24,0)),"FALSE")} -> FALSE
R18: =IF(E18<>"",E18,D18) | S18: {=IF(D18="","",IF(F18="None",0,IF(F18="Custom",L18,IF(F18="STR",Character!$J$11,IF(F18="DEX",Character!$J$12,IF(F18="Finesse",MAX(Character!$J$11,Character!$J$12),IF(F18="Auto",IF(AK18="TRUE",Character!$J$12,IF(AD18="TRUE",MAX(Character!$J$11,Character!$J$12),Character!$J$11)),0))))))+INT(Character!$H$5*IFERROR(INDEX(Data!$B$5:$B$8,MATCH(H18,Data!$A$5:$A$8,0)),0))+I18+J18)} | T18: =IF(D18="","",IF(N18<>"",N18,IF(AND(C18="Both",AG18="TRUE",AA18<>""),AA18,Z18))) | U18: =IF(D18="","",IF(G18="None",0,IF(G18="Custom",M18,IF(G18="STR",Character!$J$11,IF(G18="DEX",Character!$J$12,IF(G18="Finesse",MAX(Character!$J$11,Character!$J$12),IF(G18="Auto",IF(AK18="TRUE",Character!$J$12,IF(AD18="TRUE",MAX(Character!$J$11,Character!$J$12),Character!$J$11)),0))))))+I18+K18) | V18: =IF(T18="","",T18&IF(U18>0,"+"&U18,IF(U18<0,U18,""))) | W18: =IF(O18<>"",O18,AB18) | X18: =IF(P18<>"",P18,AC18) | Y18: =IF(C18<>"Off","",IF(OR(AE18="TRUE",$E$9="TRUE"),"Bonus Action; no ability mod to damage unless TWF Style is TRUE","Check rules: off-hand usually needs a Light weapon or Dual Wielder")) | Z18: {=IFERROR(INDEX(Data!$AC$5:$AC$24,MATCH(D18,Data!$AA$5:$AA$24,0)),"")} | AA18: {=IFERROR(INDEX(Data!$AF$5:$AF$24,MATCH(D18,Data!$AA$5:$AA$24,0)),"")} | AB18: {=IFERROR(INDEX(Data!$AD$5:$AD$24,MATCH(D18,Data!$AA$5:$AA$24,0)),"")} | AC18: {=IFERROR(INDEX(Data!$AE$5:$AE$24,MATCH(D18,Data!$AA$5:$AA$24,0)),"")} | AD18: {=IFERROR(INDEX(Data!$AG$5:$AG$24,MATCH(D18,Data!$AA$5:$AA$24,0)),"FALSE")} -> FALSE | AE18: {=IFERROR(INDEX(Data!$AH$5:$AH$24,MATCH(D18,Data!$AA$5:$AA$24,0)),"FALSE")} -> FALSE | AF18: {=IFERROR(INDEX(Data!$AI$5:$AI$24,MATCH(D18,Data!$AA$5:$AA$24,0)),"FALSE")} -> FALSE | AG18: {=IFERROR(INDEX(Data!$AJ$5:$AJ$24,MATCH(D18,Data!$AA$5:$AA$24,0)),"FALSE")} -> FALSE | AH18: {=IFERROR(INDEX(Data!$AK$5:$AK$24,MATCH(D18,Data!$AA$5:$AA$24,0)),"FALSE")} -> FALSE | AI18: {=IFERROR(INDEX(Data!$AL$5:$AL$24,MATCH(D18,Data!$AA$5:$AA$24,0)),"FALSE")} -> FALSE | AJ18: {=IFERROR(INDEX(Data!$AM$5:$AM$24,MATCH(D18,Data!$AA$5:$AA$24,0)),"FALSE")} -> FALSE | AK18: {=IFERROR(INDEX(Data!$AN$5:$AN$24,MATCH(D18,Data!$AA$5:$AA$24,0)),"FALSE")} -> FALSE | AL18: {=IFERROR(INDEX(Data!$AO$5:$AO$24,MATCH(D18,Data!$AA$5:$AA$24,0)),"FALSE")} -> FALSE
R19: =IF(E19<>"",E19,D19) | S19: {=IF(D19="","",IF(F19="None",0,IF(F19="Custom",L19,IF(F19="STR",Character!$J$11,IF(F19="DEX",Character!$J$12,IF(F19="Finesse",MAX(Character!$J$11,Character!$J$12),IF(F19="Auto",IF(AK19="TRUE",Character!$J$12,IF(AD19="TRUE",MAX(Character!$J$11,Character!$J$12),Character!$J$11)),0))))))+INT(Character!$H$5*IFERROR(INDEX(Data!$B$5:$B$8,MATCH(H19,Data!$A$5:$A$8,0)),0))+I19+J19)} | T19: =IF(D19="","",IF(N19<>"",N19,IF(AND(C19="Both",AG19="TRUE",AA19<>""),AA19,Z19))) | U19: =IF(D19="","",IF(G19="None",0,IF(G19="Custom",M19,IF(G19="STR",Character!$J$11,IF(G19="DEX",Character!$J$12,IF(G19="Finesse",MAX(Character!$J$11,Character!$J$12),IF(G19="Auto",IF(AK19="TRUE",Character!$J$12,IF(AD19="TRUE",MAX(Character!$J$11,Character!$J$12),Character!$J$11)),0))))))+I19+K19) | V19: =IF(T19="","",T19&IF(U19>0,"+"&U19,IF(U19<0,U19,""))) | W19: =IF(O19<>"",O19,AB19) | X19: =IF(P19<>"",P19,AC19) | Y19: =IF(C19<>"Off","",IF(OR(AE19="TRUE",$E$9="TRUE"),"Bonus Action; no ability mod to damage unless TWF Style is TRUE","Check rules: off-hand usually needs a Light weapon or Dual Wielder")) | Z19: {=IFERROR(INDEX(Data!$AC$5:$AC$24,MATCH(D19,Data!$AA$5:$AA$24,0)),"")} | AA19: {=IFERROR(INDEX(Data!$AF$5:$AF$24,MATCH(D19,Data!$AA$5:$AA$24,0)),"")} | AB19: {=IFERROR(INDEX(Data!$AD$5:$AD$24,MATCH(D19,Data!$AA$5:$AA$24,0)),"")} | AC19: {=IFERROR(INDEX(Data!$AE$5:$AE$24,MATCH(D19,Data!$AA$5:$AA$24,0)),"")} | AD19: {=IFERROR(INDEX(Data!$AG$5:$AG$24,MATCH(D19,Data!$AA$5:$AA$24,0)),"FALSE")} -> FALSE | AE19: {=IFERROR(INDEX(Data!$AH$5:$AH$24,MATCH(D19,Data!$AA$5:$AA$24,0)),"FALSE")} -> FALSE | AF19: {=IFERROR(INDEX(Data!$AI$5:$AI$24,MATCH(D19,Data!$AA$5:$AA$24,0)),"FALSE")} -> FALSE | AG19: {=IFERROR(INDEX(Data!$AJ$5:$AJ$24,MATCH(D19,Data!$AA$5:$AA$24,0)),"FALSE")} -> FALSE | AH19: {=IFERROR(INDEX(Data!$AK$5:$AK$24,MATCH(D19,Data!$AA$5:$AA$24,0)),"FALSE")} -> FALSE | AI19: {=IFERROR(INDEX(Data!$AL$5:$AL$24,MATCH(D19,Data!$AA$5:$AA$24,0)),"FALSE")} -> FALSE | AJ19: {=IFERROR(INDEX(Data!$AM$5:$AM$24,MATCH(D19,Data!$AA$5:$AA$24,0)),"FALSE")} -> FALSE | AK19: {=IFERROR(INDEX(Data!$AN$5:$AN$24,MATCH(D19,Data!$AA$5:$AA$24,0)),"FALSE")} -> FALSE | AL19: {=IFERROR(INDEX(Data!$AO$5:$AO$24,MATCH(D19,Data!$AA$5:$AA$24,0)),"FALSE")} -> FALSE
R20: =IF(E20<>"",E20,D20) | S20: {=IF(D20="","",IF(F20="None",0,IF(F20="Custom",L20,IF(F20="STR",Character!$J$11,IF(F20="DEX",Character!$J$12,IF(F20="Finesse",MAX(Character!$J$11,Character!$J$12),IF(F20="Auto",IF(AK20="TRUE",Character!$J$12,IF(AD20="TRUE",MAX(Character!$J$11,Character!$J$12),Character!$J$11)),0))))))+INT(Character!$H$5*IFERROR(INDEX(Data!$B$5:$B$8,MATCH(H20,Data!$A$5:$A$8,0)),0))+I20+J20)} | T20: =IF(D20="","",IF(N20<>"",N20,IF(AND(C20="Both",AG20="TRUE",AA20<>""),AA20,Z20))) | U20: =IF(D20="","",IF(G20="None",0,IF(G20="Custom",M20,IF(G20="STR",Character!$J$11,IF(G20="DEX",Character!$J$12,IF(G20="Finesse",MAX(Character!$J$11,Character!$J$12),IF(G20="Auto",IF(AK20="TRUE",Character!$J$12,IF(AD20="TRUE",MAX(Character!$J$11,Character!$J$12),Character!$J$11)),0))))))+I20+K20) | V20: =IF(T20="","",T20&IF(U20>0,"+"&U20,IF(U20<0,U20,""))) | W20: =IF(O20<>"",O20,AB20) | X20: =IF(P20<>"",P20,AC20) | Y20: =IF(C20<>"Off","",IF(OR(AE20="TRUE",$E$9="TRUE"),"Bonus Action; no ability mod to damage unless TWF Style is TRUE","Check rules: off-hand usually needs a Light weapon or Dual Wielder")) | Z20: {=IFERROR(INDEX(Data!$AC$5:$AC$24,MATCH(D20,Data!$AA$5:$AA$24,0)),"")} | AA20: {=IFERROR(INDEX(Data!$AF$5:$AF$24,MATCH(D20,Data!$AA$5:$AA$24,0)),"")} | AB20: {=IFERROR(INDEX(Data!$AD$5:$AD$24,MATCH(D20,Data!$AA$5:$AA$24,0)),"")} | AC20: {=IFERROR(INDEX(Data!$AE$5:$AE$24,MATCH(D20,Data!$AA$5:$AA$24,0)),"")} | AD20: {=IFERROR(INDEX(Data!$AG$5:$AG$24,MATCH(D20,Data!$AA$5:$AA$24,0)),"FALSE")} -> FALSE | AE20: {=IFERROR(INDEX(Data!$AH$5:$AH$24,MATCH(D20,Data!$AA$5:$AA$24,0)),"FALSE")} -> FALSE | AF20: {=IFERROR(INDEX(Data!$AI$5:$AI$24,MATCH(D20,Data!$AA$5:$AA$24,0)),"FALSE")} -> FALSE | AG20: {=IFERROR(INDEX(Data!$AJ$5:$AJ$24,MATCH(D20,Data!$AA$5:$AA$24,0)),"FALSE")} -> FALSE | AH20: {=IFERROR(INDEX(Data!$AK$5:$AK$24,MATCH(D20,Data!$AA$5:$AA$24,0)),"FALSE")} -> FALSE | AI20: {=IFERROR(INDEX(Data!$AL$5:$AL$24,MATCH(D20,Data!$AA$5:$AA$24,0)),"FALSE")} -> FALSE | AJ20: {=IFERROR(INDEX(Data!$AM$5:$AM$24,MATCH(D20,Data!$AA$5:$AA$24,0)),"FALSE")} -> FALSE | AK20: {=IFERROR(INDEX(Data!$AN$5:$AN$24,MATCH(D20,Data!$AA$5:$AA$24,0)),"FALSE")} -> FALSE | AL20: {=IFERROR(INDEX(Data!$AO$5:$AO$24,MATCH(D20,Data!$AA$5:$AA$24,0)),"FALSE")} -> FALSE
R21: =IF(E21<>"",E21,D21) | S21: {=IF(D21="","",IF(F21="None",0,IF(F21="Custom",L21,IF(F21="STR",Character!$J$11,IF(F21="DEX",Character!$J$12,IF(F21="Finesse",MAX(Character!$J$11,Character!$J$12),IF(F21="Auto",IF(AK21="TRUE",Character!$J$12,IF(AD21="TRUE",MAX(Character!$J$11,Character!$J$12),Character!$J$11)),0))))))+INT(Character!$H$5*IFERROR(INDEX(Data!$B$5:$B$8,MATCH(H21,Data!$A$5:$A$8,0)),0))+I21+J21)} | T21: =IF(D21="","",IF(N21<>"",N21,IF(AND(C21="Both",AG21="TRUE",AA21<>""),AA21,Z21))) | U21: =IF(D21="","",IF(G21="None",0,IF(G21="Custom",M21,IF(G21="STR",Character!$J$11,IF(G21="DEX",Character!$J$12,IF(G21="Finesse",MAX(Character!$J$11,Character!$J$12),IF(G21="Auto",IF(AK21="TRUE",Character!$J$12,IF(AD21="TRUE",MAX(Character!$J$11,Character!$J$12),Character!$J$11)),0))))))+I21+K21) | V21: =IF(T21="","",T21&IF(U21>0,"+"&U21,IF(U21<0,U21,""))) | W21: =IF(O21<>"",O21,AB21) | X21: =IF(P21<>"",P21,AC21) | Y21: =IF(C21<>"Off","",IF(OR(AE21="TRUE",$E$9="TRUE"),"Bonus Action; no ability mod to damage unless TWF Style is TRUE","Check rules: off-hand usually needs a Light weapon or Dual Wielder")) | Z21: {=IFERROR(INDEX(Data!$AC$5:$AC$24,MATCH(D21,Data!$AA$5:$AA$24,0)),"")} | AA21: {=IFERROR(INDEX(Data!$AF$5:$AF$24,MATCH(D21,Data!$AA$5:$AA$24,0)),"")} | AB21: {=IFERROR(INDEX(Data!$AD$5:$AD$24,MATCH(D21,Data!$AA$5:$AA$24,0)),"")} | AC21: {=IFERROR(INDEX(Data!$AE$5:$AE$24,MATCH(D21,Data!$AA$5:$AA$24,0)),"")} | AD21: {=IFERROR(INDEX(Data!$AG$5:$AG$24,MATCH(D21,Data!$AA$5:$AA$24,0)),"FALSE")} -> FALSE | AE21: {=IFERROR(INDEX(Data!$AH$5:$AH$24,MATCH(D21,Data!$AA$5:$AA$24,0)),"FALSE")} -> FALSE | AF21: {=IFERROR(INDEX(Data!$AI$5:$AI$24,MATCH(D21,Data!$AA$5:$AA$24,0)),"FALSE")} -> FALSE | AG21: {=IFERROR(INDEX(Data!$AJ$5:$AJ$24,MATCH(D21,Data!$AA$5:$AA$24,0)),"FALSE")} -> FALSE | AH21: {=IFERROR(INDEX(Data!$AK$5:$AK$24,MATCH(D21,Data!$AA$5:$AA$24,0)),"FALSE")} -> FALSE | AI21: {=IFERROR(INDEX(Data!$AL$5:$AL$24,MATCH(D21,Data!$AA$5:$AA$24,0)),"FALSE")} -> FALSE | AJ21: {=IFERROR(INDEX(Data!$AM$5:$AM$24,MATCH(D21,Data!$AA$5:$AA$24,0)),"FALSE")} -> FALSE | AK21: {=IFERROR(INDEX(Data!$AN$5:$AN$24,MATCH(D21,Data!$AA$5:$AA$24,0)),"FALSE")} -> FALSE | AL21: {=IFERROR(INDEX(Data!$AO$5:$AO$24,MATCH(D21,Data!$AA$5:$AA$24,0)),"FALSE")} -> FALSE
R22: =IF(E22<>"",E22,D22) | S22: {=IF(D22="","",IF(F22="None",0,IF(F22="Custom",L22,IF(F22="STR",Character!$J$11,IF(F22="DEX",Character!$J$12,IF(F22="Finesse",MAX(Character!$J$11,Character!$J$12),IF(F22="Auto",IF(AK22="TRUE",Character!$J$12,IF(AD22="TRUE",MAX(Character!$J$11,Character!$J$12),Character!$J$11)),0))))))+INT(Character!$H$5*IFERROR(INDEX(Data!$B$5:$B$8,MATCH(H22,Data!$A$5:$A$8,0)),0))+I22+J22)} | T22: =IF(D22="","",IF(N22<>"",N22,IF(AND(C22="Both",AG22="TRUE",AA22<>""),AA22,Z22))) | U22: =IF(D22="","",IF(G22="None",0,IF(G22="Custom",M22,IF(G22="STR",Character!$J$11,IF(G22="DEX",Character!$J$12,IF(G22="Finesse",MAX(Character!$J$11,Character!$J$12),IF(G22="Auto",IF(AK22="TRUE",Character!$J$12,IF(AD22="TRUE",MAX(Character!$J$11,Character!$J$12),Character!$J$11)),0))))))+I22+K22) | V22: =IF(T22="","",T22&IF(U22>0,"+"&U22,IF(U22<0,U22,""))) | W22: =IF(O22<>"",O22,AB22) | X22: =IF(P22<>"",P22,AC22) | Y22: =IF(C22<>"Off","",IF(OR(AE22="TRUE",$E$9="TRUE"),"Bonus Action; no ability mod to damage unless TWF Style is TRUE","Check rules: off-hand usually needs a Light weapon or Dual Wielder")) | Z22: {=IFERROR(INDEX(Data!$AC$5:$AC$24,MATCH(D22,Data!$AA$5:$AA$24,0)),"")} | AA22: {=IFERROR(INDEX(Data!$AF$5:$AF$24,MATCH(D22,Data!$AA$5:$AA$24,0)),"")} | AB22: {=IFERROR(INDEX(Data!$AD$5:$AD$24,MATCH(D22,Data!$AA$5:$AA$24,0)),"")} | AC22: {=IFERROR(INDEX(Data!$AE$5:$AE$24,MATCH(D22,Data!$AA$5:$AA$24,0)),"")} | AD22: {=IFERROR(INDEX(Data!$AG$5:$AG$24,MATCH(D22,Data!$AA$5:$AA$24,0)),"FALSE")} -> FALSE | AE22: {=IFERROR(INDEX(Data!$AH$5:$AH$24,MATCH(D22,Data!$AA$5:$AA$24,0)),"FALSE")} -> FALSE | AF22: {=IFERROR(INDEX(Data!$AI$5:$AI$24,MATCH(D22,Data!$AA$5:$AA$24,0)),"FALSE")} -> FALSE | AG22: {=IFERROR(INDEX(Data!$AJ$5:$AJ$24,MATCH(D22,Data!$AA$5:$AA$24,0)),"FALSE")} -> FALSE | AH22: {=IFERROR(INDEX(Data!$AK$5:$AK$24,MATCH(D22,Data!$AA$5:$AA$24,0)),"FALSE")} -> FALSE | AI22: {=IFERROR(INDEX(Data!$AL$5:$AL$24,MATCH(D22,Data!$AA$5:$AA$24,0)),"FALSE")} -> FALSE | AJ22: {=IFERROR(INDEX(Data!$AM$5:$AM$24,MATCH(D22,Data!$AA$5:$AA$24,0)),"FALSE")} -> FALSE | AK22: {=IFERROR(INDEX(Data!$AN$5:$AN$24,MATCH(D22,Data!$AA$5:$AA$24,0)),"FALSE")} -> FALSE | AL22: {=IFERROR(INDEX(Data!$AO$5:$AO$24,MATCH(D22,Data!$AA$5:$AA$24,0)),"FALSE")} -> FALSE
R23: =IF(E23<>"",E23,D23) | S23: {=IF(D23="","",IF(F23="None",0,IF(F23="Custom",L23,IF(F23="STR",Character!$J$11,IF(F23="DEX",Character!$J$12,IF(F23="Finesse",MAX(Character!$J$11,Character!$J$12),IF(F23="Auto",IF(AK23="TRUE",Character!$J$12,IF(AD23="TRUE",MAX(Character!$J$11,Character!$J$12),Character!$J$11)),0))))))+INT(Character!$H$5*IFERROR(INDEX(Data!$B$5:$B$8,MATCH(H23,Data!$A$5:$A$8,0)),0))+I23+J23)} | T23: =IF(D23="","",IF(N23<>"",N23,IF(AND(C23="Both",AG23="TRUE",AA23<>""),AA23,Z23))) | U23: =IF(D23="","",IF(G23="None",0,IF(G23="Custom",M23,IF(G23="STR",Character!$J$11,IF(G23="DEX",Character!$J$12,IF(G23="Finesse",MAX(Character!$J$11,Character!$J$12),IF(G23="Auto",IF(AK23="TRUE",Character!$J$12,IF(AD23="TRUE",MAX(Character!$J$11,Character!$J$12),Character!$J$11)),0))))))+I23+K23) | V23: =IF(T23="","",T23&IF(U23>0,"+"&U23,IF(U23<0,U23,""))) | W23: =IF(O23<>"",O23,AB23) | X23: =IF(P23<>"",P23,AC23) | Y23: =IF(C23<>"Off","",IF(OR(AE23="TRUE",$E$9="TRUE"),"Bonus Action; no ability mod to damage unless TWF Style is TRUE","Check rules: off-hand usually needs a Light weapon or Dual Wielder")) | Z23: {=IFERROR(INDEX(Data!$AC$5:$AC$24,MATCH(D23,Data!$AA$5:$AA$24,0)),"")} | AA23: {=IFERROR(INDEX(Data!$AF$5:$AF$24,MATCH(D23,Data!$AA$5:$AA$24,0)),"")} | AB23: {=IFERROR(INDEX(Data!$AD$5:$AD$24,MATCH(D23,Data!$AA$5:$AA$24,0)),"")} | AC23: {=IFERROR(INDEX(Data!$AE$5:$AE$24,MATCH(D23,Data!$AA$5:$AA$24,0)),"")} | AD23: {=IFERROR(INDEX(Data!$AG$5:$AG$24,MATCH(D23,Data!$AA$5:$AA$24,0)),"FALSE")} -> FALSE | AE23: {=IFERROR(INDEX(Data!$AH$5:$AH$24,MATCH(D23,Data!$AA$5:$AA$24,0)),"FALSE")} -> FALSE | AF23: {=IFERROR(INDEX(Data!$AI$5:$AI$24,MATCH(D23,Data!$AA$5:$AA$24,0)),"FALSE")} -> FALSE | AG23: {=IFERROR(INDEX(Data!$AJ$5:$AJ$24,MATCH(D23,Data!$AA$5:$AA$24,0)),"FALSE")} -> FALSE | AH23: {=IFERROR(INDEX(Data!$AK$5:$AK$24,MATCH(D23,Data!$AA$5:$AA$24,0)),"FALSE")} -> FALSE | AI23: {=IFERROR(INDEX(Data!$AL$5:$AL$24,MATCH(D23,Data!$AA$5:$AA$24,0)),"FALSE")} -> FALSE | AJ23: {=IFERROR(INDEX(Data!$AM$5:$AM$24,MATCH(D23,Data!$AA$5:$AA$24,0)),"FALSE")} -> FALSE | AK23: {=IFERROR(INDEX(Data!$AN$5:$AN$24,MATCH(D23,Data!$AA$5:$AA$24,0)),"FALSE")} -> FALSE | AL23: {=IFERROR(INDEX(Data!$AO$5:$AO$24,MATCH(D23,Data!$AA$5:$AA$24,0)),"FALSE")} -> FALSE
R24: =IF(E24<>"",E24,D24) | S24: {=IF(D24="","",IF(F24="None",0,IF(F24="Custom",L24,IF(F24="STR",Character!$J$11,IF(F24="DEX",Character!$J$12,IF(F24="Finesse",MAX(Character!$J$11,Character!$J$12),IF(F24="Auto",IF(AK24="TRUE",Character!$J$12,IF(AD24="TRUE",MAX(Character!$J$11,Character!$J$12),Character!$J$11)),0))))))+INT(Character!$H$5*IFERROR(INDEX(Data!$B$5:$B$8,MATCH(H24,Data!$A$5:$A$8,0)),0))+I24+J24)} | T24: =IF(D24="","",IF(N24<>"",N24,IF(AND(C24="Both",AG24="TRUE",AA24<>""),AA24,Z24))) | U24: =IF(D24="","",IF(G24="None",0,IF(G24="Custom",M24,IF(G24="STR",Character!$J$11,IF(G24="DEX",Character!$J$12,IF(G24="Finesse",MAX(Character!$J$11,Character!$J$12),IF(G24="Auto",IF(AK24="TRUE",Character!$J$12,IF(AD24="TRUE",MAX(Character!$J$11,Character!$J$12),Character!$J$11)),0))))))+I24+K24) | V24: =IF(T24="","",T24&IF(U24>0,"+"&U24,IF(U24<0,U24,""))) | W24: =IF(O24<>"",O24,AB24) | X24: =IF(P24<>"",P24,AC24) | Y24: =IF(C24<>"Off","",IF(OR(AE24="TRUE",$E$9="TRUE"),"Bonus Action; no ability mod to damage unless TWF Style is TRUE","Check rules: off-hand usually needs a Light weapon or Dual Wielder")) | Z24: {=IFERROR(INDEX(Data!$AC$5:$AC$24,MATCH(D24,Data!$AA$5:$AA$24,0)),"")} | AA24: {=IFERROR(INDEX(Data!$AF$5:$AF$24,MATCH(D24,Data!$AA$5:$AA$24,0)),"")} | AB24: {=IFERROR(INDEX(Data!$AD$5:$AD$24,MATCH(D24,Data!$AA$5:$AA$24,0)),"")} | AC24: {=IFERROR(INDEX(Data!$AE$5:$AE$24,MATCH(D24,Data!$AA$5:$AA$24,0)),"")} | AD24: {=IFERROR(INDEX(Data!$AG$5:$AG$24,MATCH(D24,Data!$AA$5:$AA$24,0)),"FALSE")} -> FALSE | AE24: {=IFERROR(INDEX(Data!$AH$5:$AH$24,MATCH(D24,Data!$AA$5:$AA$24,0)),"FALSE")} -> FALSE | AF24: {=IFERROR(INDEX(Data!$AI$5:$AI$24,MATCH(D24,Data!$AA$5:$AA$24,0)),"FALSE")} -> FALSE | AG24: {=IFERROR(INDEX(Data!$AJ$5:$AJ$24,MATCH(D24,Data!$AA$5:$AA$24,0)),"FALSE")} -> FALSE | AH24: {=IFERROR(INDEX(Data!$AK$5:$AK$24,MATCH(D24,Data!$AA$5:$AA$24,0)),"FALSE")} -> FALSE | AI24: {=IFERROR(INDEX(Data!$AL$5:$AL$24,MATCH(D24,Data!$AA$5:$AA$24,0)),"FALSE")} -> FALSE | AJ24: {=IFERROR(INDEX(Data!$AM$5:$AM$24,MATCH(D24,Data!$AA$5:$AA$24,0)),"FALSE")} -> FALSE | AK24: {=IFERROR(INDEX(Data!$AN$5:$AN$24,MATCH(D24,Data!$AA$5:$AA$24,0)),"FALSE")} -> FALSE | AL24: {=IFERROR(INDEX(Data!$AO$5:$AO$24,MATCH(D24,Data!$AA$5:$AA$24,0)),"FALSE")} -> FALSE
... R28: =IF(E28<>"",E28,D28) | S28: {=IF(D28="","",IF(F28="None",0,IF(F28="Custom",L28,IF(F28="STR",Character!$J$11,IF(F28="DEX",Character!$J$12,IF(F28="Finesse",MAX(Character!$J$11,Character!$J$12),IF(F28="Auto",IF(AK28="TRUE",Character!$J$12,IF(AD28="TRUE",MAX(Character!$J$11,Character!$J$12),Character!$J$11)),0))))))+INT(Character!$H$5*IFERROR(INDEX(Data!$B$5:$B$8,MATCH(H28,Data!$A$5:$A$8,0)),0))+I28+J28)} | T28: =IF(D28="","",IF(N28<>"",N28,IF(AND(C28="Both",AG28="TRUE",AA28<>""),AA28,Z28))) | U28: =IF(D28="","",IF(G28="None",0,IF(G28="Custom",M28,IF(G28="STR",Character!$J$11,IF(G28="DEX",Character!$J$12,IF(G28="Finesse",MAX(Character!$J$11,Character!$J$12),IF(G28="Auto",IF(AK28="TRUE",Character!$J$12,IF(AD28="TRUE",MAX(Character!$J$11,Character!$J$12),Character!$J$11)),0))))))+I28+K28) | V28: =IF(T28="","",T28&IF(U28>0,"+"&U28,IF(U28<0,U28,""))) | W28: =IF(O28<>"",O28,AB28) | X28: =IF(P28<>"",P28,AC28) | Y28: =IF(C28<>"Off","",IF(OR(AE28="TRUE",$E$9="TRUE"),"Bonus Action; no ability mod to damage unless TWF Style is TRUE","Check rules: off-hand usually needs a Light weapon or Dual Wielder")) | Z28: {=IFERROR(INDEX(Data!$AC$5:$AC$24,MATCH(D28,Data!$AA$5:$AA$24,0)),"")} | AA28: {=IFERROR(INDEX(Data!$AF$5:$AF$24,MATCH(D28,Data!$AA$5:$AA$24,0)),"")} | AB28: {=IFERROR(INDEX(Data!$AD$5:$AD$24,MATCH(D28,Data!$AA$5:$AA$24,0)),"")} | AC28: {=IFERROR(INDEX(Data!$AE$5:$AE$24,MATCH(D28,Data!$AA$5:$AA$24,0)),"")} | AD28: {=IFERROR(INDEX(Data!$AG$5:$AG$24,MATCH(D28,Data!$AA$5:$AA$24,0)),"FALSE")} -> FALSE | AE28: {=IFERROR(INDEX(Data!$AH$5:$AH$24,MATCH(D28,Data!$AA$5:$AA$24,0)),"FALSE")} -> FALSE | AF28: {=IFERROR(INDEX(Data!$AI$5:$AI$24,MATCH(D28,Data!$AA$5:$AA$24,0)),"FALSE")} -> FALSE | AG28: {=IFERROR(INDEX(Data!$AJ$5:$AJ$24,MATCH(D28,Data!$AA$5:$AA$24,0)),"FALSE")} -> FALSE | AH28: {=IFERROR(INDEX(Data!$AK$5:$AK$24,MATCH(D28,Data!$AA$5:$AA$24,0)),"FALSE")} -> FALSE | AI28: {=IFERROR(INDEX(Data!$AL$5:$AL$24,MATCH(D28,Data!$AA$5:$AA$24,0)),"FALSE")} -> FALSE | AJ28: {=IFERROR(INDEX(Data!$AM$5:$AM$24,MATCH(D28,Data!$AA$5:$AA$24,0)),"FALSE")} -> FALSE | AK28: {=IFERROR(INDEX(Data!$AN$5:$AN$24,MATCH(D28,Data!$AA$5:$AA$24,0)),"FALSE")} -> FALSE | AL28: {=IFERROR(INDEX(Data!$AO$5:$AO$24,MATCH(D28,Data!$AA$5:$AA$24,0)),"FALSE")} -> FALSE
A30: Resources | G30: Conditions / Combat Notes
A31: Resource | B31: Current | C31: Max | D31: Recharge | E31: Notes | G31: Examples: - Concentrating on Bless - Rage active - Invisible until end of turn - Divine Fury: first hit each turn while raging

Sheet Features
A1: Show | B1: Fav | C1: Source | D1: Name | E1: Action | F1: Uses Current | G1: Uses Max | H1: Recharge | I1: Roll Formula | J1: Roll Label | K1: Short Text | L1: Full Text
A2: TRUE | B2: TRUE | C2: Class | D2: Rage | E2: Bonus Action | F2: 3 | G2: 3 | H2: Long Rest | J2: Use | K2: Enter Rage | L2: Enter a rage for 1 minute. Normal rage rules apply.
A3: TRUE | B3: FALSE | C3: Class | D3: Unarmored Defense | E3: Passive | H3: Always | K3: AC formula | L3: While unarmored, your AC equals 10 + your Dexterity modifier + your Constitution modifier. You can use a shield and still gain this benefit.
A4: TRUE | B4: FALSE | C4: Class | D4: Reckless Attack | E4: Passive | H4: Always | K4: Attack option | L4: Advantage on STR melee attacks | M4: You can throw aside all concern for defense to attack with fierce desperation. When you make your first attack on your turn, you can decide to attack recklessly. Doing so gives you advantage on STR-based melee weapon attack rolls this turn, but attack rolls against you have advantage until your next turn.
A5: TRUE | B5: FALSE | C5: Class | D5: Danger Sense | E5: Passive | H5: Always | K5: Save reminder | L5: Advantage on Dex saves vs visible effects | M5: You have advantage on Dexterity saving throws against effects you can see, such as traps and spells. You do not gain this benefit if you are blinded, deafened, or incapacitated.
A6: TRUE | B6: FALSE | C6: Class | D6: Fast Movement | E6: Passive | H6: Always | K6: +10 spell | L6: Not in heavy armor | M6: Your speed increases by 10 feet while you aren't wearing heavy armor.
A7: TRUE | B7: FALSE | C7: Subclass | D7: Divine Fury | E7: Passive | H7: While Raging | I7: 1d6 + floor(BarbarianLevel/2) | J7: Roll Bonus Damage | K7: First hit each turn while raging | L7: On each of your turns while your Rage is active, the first creature you hit with a weapon or an Unarmed Strike takes extra damage equal to 1d6 plus half your Barbarian level, rounded down. The extra damage is Necrotic or Radiant; you choose the type each time.
A8: TRUE | B8: TRUE | C8: Custom | D8: Lion's Gambit | E8: Reaction | F8: 3 | G8: 3 | H8: Short Rest | I8: 1d20 + WeaponAttack | J8: Roll Attack | K8: Reaction melee strike | L8: After taking damage from a creature within 5 feet, make a melee weapon attack against that creature. On a hit, add bonus damage equal to half your level.
A9: TRUE | B9: TRUE | C9: Class | D9: Second Wind | E9: Bonus Action | F9: 1 | G9: 1 | H9: Short Rest | I9: 1d10 + FighterLevel | J9: Roll Healing | K9: Bonus action self-heal | L9: You have a limited well of stamina you can draw on to protect yourself from harm. On your turn, you can use a Bonus Action to regain hit points equal to 1d10 + your Fighter level.
A10: TRUE | B10: TRUE | C10: Class | D10: Innate Sorcery | E10: Bonus Action | F10: 2 | G10: 2 | H10: Long Rest | J10: Use | K10: +1 spell DC, adv on Sorcerer spell attacks | L10: As a Bonus Action, you can unleash your innate magic for 1 minute. During that time, the spell save DC of your Sorcerer spells increases by 1, and you have Advantage on the attack rolls of Sorcerer spells you cast.
A11: TRUE | B11: FALSE | C11: Species | D11: Lucky | E11: Passive | H11: Always | K11: Reroll 1s on d20 tests | L11: When you roll a 1 on the d20 of a d20 Test, you can reroll the die, and you must use the new roll.
A12: FALSE | B12: FALSE
A13: FALSE | B13: FALSE
A14: FALSE | B14: FALSE
A15: FALSE | B15: FALSE
A16: FALSE | B16: FALSE
A17: FALSE | B17: FALSE
A18: FALSE | B18: FALSE
A19: FALSE | B19: FALSE
A20: FALSE
A21: FALSE
A22: FALSE
A23: FALSE
A24: FALSE
A25: FALSE
A26: FALSE
A27: FALSE
A28: FALSE
A29: FALSE
A30: FALSE
A31: FALSE
... A1000: FALSE

Sheet Spells
A1: Spells
A3: Spell Slots | E3: Known / Prepared Spells
A4: Level | B4: Current | C4: Max | E4: Visible | F4: Favorite | G4: Prepared | H4: Spell Name | I4: Level | J4: School | K4: Casting Time | L4: Cast Type | M4: Attack Mod Source | N4: Save DC Source | O4: Save Ability | P4: Effect Formula | Q4: Damage Type | R4: Concentration | S4: Ritual | T4: Duration | U4: Slot Use | V4: Active Effect | W4: Scaling Type | X4: Scaling Data | Y4: Derived Roll Bonus | Z4: Derived Save DC | AA4: Notes
A5: Cantrip | E5: TRUE | F5: TRUE | G5: TRUE | H5: Shield | I5: {=IFERROR(INDEX(SpellData!$B$4:$B$20,MATCH(H5,SpellData!$A$4:$A$20,0)),"")} -> 1 | J5: {=IFERROR(INDEX(SpellData!$C$4:$C$20,MATCH(H5,SpellData!$A$4:$A$20,0)),"")} -> Abjuration | K5: {=IFERROR(INDEX(SpellData!$D$4:$D$20,MATCH(H5,SpellData!$A$4:$A$20,0)),"")} -> Reaction | L5: {=IFERROR(INDEX(SpellData!$E$4:$E$20,MATCH(H5,SpellData!$A$4:$A$20,0)),"")} -> Buff | M5: {=IFERROR(INDEX(SpellData!$F$4:$F$20,MATCH(H5,SpellData!$A$4:$A$20,0)),"")} | N5: {=IFERROR(INDEX(SpellData!$G$4:$G$20,MATCH(H5,SpellData!$A$4:$A$20,0)),"")} | O5: {=IFERROR(INDEX(SpellData!$H$4:$H$20,MATCH(H5,SpellData!$A$4:$A$20,0)),"")} | P5: {=IFERROR(INDEX(SpellData!$I$4:$I$20,MATCH(H5,SpellData!$A$4:$A$20,0)),"")} | Q5: {=IFERROR(INDEX(SpellData!$J$4:$J$20,MATCH(H5,SpellData!$A$4:$A$20,0)),"")} -> +5 AC | R5: {=IFERROR(INDEX(SpellData!$K$4:$K$20,MATCH(H5,SpellData!$A$4:$A$20,0)),"")} -> FALSE | S5: {=IFERROR(INDEX(SpellData!$L$4:$L$20,MATCH(H5,SpellData!$A$4:$A$20,0)),"")} -> FALSE | T5: {=IFERROR(INDEX(SpellData!$M$4:$M$20,MATCH(H5,SpellData!$A$4:$A$20,0)),"")} -> Until start of your next turn | U5: {=IFERROR(INDEX(SpellData!$N$4:$N$20,MATCH(H5,SpellData!$A$4:$A$20,0)),"")} -> Auto | V5: {=IFERROR(INDEX(SpellData!$O$4:$O$20,MATCH(H5,SpellData!$A$4:$A$20,0)),"")} -> +5 AC | W5: {=IFERROR(INDEX(SpellData!$P$4:$P$20,MATCH(H5,SpellData!$A$4:$A$20,0)),"")} -> None | X5: {=IFERROR(INDEX(SpellData!$Q$4:$Q$20,MATCH(H5,SpellData!$A$4:$A$20,0)),"")} | Y5: =IF(M5="Spell Attack",Character!$E$30,"") | Z5: =IF(N5="Spell DC",Character!$E$31,"") | AB5: {=IFERROR(INDEX(SpellData!$R$4:$R$20,MATCH(H5,SpellData!$A$4:$A$20,0)),"")} -> Cast when hit or targeted by Magic Missile
A6: 1 | B6: 0 | C6: 0 | E6: TRUE | F6: TRUE | G6: TRUE | H6: Fire Bolt | I6: {=IFERROR(INDEX(SpellData!$B$4:$B$20,MATCH(H6,SpellData!$A$4:$A$20,0)),"")} -> 0 | J6: {=IFERROR(INDEX(SpellData!$C$4:$C$20,MATCH(H6,SpellData!$A$4:$A$20,0)),"")} -> Evocation | K6: {=IFERROR(INDEX(SpellData!$D$4:$D$20,MATCH(H6,SpellData!$A$4:$A$20,0)),"")} -> Action | L6: {=IFERROR(INDEX(SpellData!$E$4:$E$20,MATCH(H6,SpellData!$A$4:$A$20,0)),"")} -> Attack | M6: {=IFERROR(INDEX(SpellData!$F$4:$F$20,MATCH(H6,SpellData!$A$4:$A$20,0)),"")} -> Spell Attack | N6: {=IFERROR(INDEX(SpellData!$G$4:$G$20,MATCH(H6,SpellData!$A$4:$A$20,0)),"")} | O6: {=IFERROR(INDEX(SpellData!$H$4:$H$20,MATCH(H6,SpellData!$A$4:$A$20,0)),"")} | P6: {=IFERROR(INDEX(SpellData!$I$4:$I$20,MATCH(H6,SpellData!$A$4:$A$20,0)),"")} -> 1d10 | Q6: {=IFERROR(INDEX(SpellData!$J$4:$J$20,MATCH(H6,SpellData!$A$4:$A$20,0)),"")} -> Fire | R6: {=IFERROR(INDEX(SpellData!$K$4:$K$20,MATCH(H6,SpellData!$A$4:$A$20,0)),"")} -> FALSE | S6: {=IFERROR(INDEX(SpellData!$L$4:$L$20,MATCH(H6,SpellData!$A$4:$A$20,0)),"")} -> FALSE | T6: {=IFERROR(INDEX(SpellData!$M$4:$M$20,MATCH(H6,SpellData!$A$4:$A$20,0)),"")} -> Instant | U6: {=IFERROR(INDEX(SpellData!$N$4:$N$20,MATCH(H6,SpellData!$A$4:$A$20,0)),"")} -> None | V6: {=IFERROR(INDEX(SpellData!$O$4:$O$20,MATCH(H6,SpellData!$A$4:$A$20,0)),"")} | W6: {=IFERROR(INDEX(SpellData!$P$4:$P$20,MATCH(H6,SpellData!$A$4:$A$20,0)),"")} -> CantripDice | X6: {=IFERROR(INDEX(SpellData!$Q$4:$Q$20,MATCH(H6,SpellData!$A$4:$A$20,0)),"")} -> 5:2d10;11:3d10;17:4d10 | Y6: =IF(M6="Spell Attack",Character!$E$30,"") | Z6: =IF(N6="Spell DC",Character!$E$31,"") | AB6: {=IFERROR(INDEX(SpellData!$R$4:$R$20,MATCH(H6,SpellData!$A$4:$A$20,0)),"")}
A7: 2 | B7: 0 | C7: 0 | E7: TRUE | F7: FALSE | G7: TRUE | H7: Fireball | I7: {=IFERROR(INDEX(SpellData!$B$4:$B$20,MATCH(H7,SpellData!$A$4:$A$20,0)),"")} -> 3 | J7: {=IFERROR(INDEX(SpellData!$C$4:$C$20,MATCH(H7,SpellData!$A$4:$A$20,0)),"")} -> Evocation | K7: {=IFERROR(INDEX(SpellData!$D$4:$D$20,MATCH(H7,SpellData!$A$4:$A$20,0)),"")} -> Action | L7: {=IFERROR(INDEX(SpellData!$E$4:$E$20,MATCH(H7,SpellData!$A$4:$A$20,0)),"")} -> Save | M7: {=IFERROR(INDEX(SpellData!$F$4:$F$20,MATCH(H7,SpellData!$A$4:$A$20,0)),"")} | N7: {=IFERROR(INDEX(SpellData!$G$4:$G$20,MATCH(H7,SpellData!$A$4:$A$20,0)),"")} -> Spell DC | O7: {=IFERROR(INDEX(SpellData!$H$4:$H$20,MATCH(H7,SpellData!$A$4:$A$20,0)),"")} -> DEX | P7: {=IFERROR(INDEX(SpellData!$I$4:$I$20,MATCH(H7,SpellData!$A$4:$A$20,0)),"")} -> 8d6 | Q7: {=IFERROR(INDEX(SpellData!$J$4:$J$20,MATCH(H7,SpellData!$A$4:$A$20,0)),"")} -> Fire | R7: {=IFERROR(INDEX(SpellData!$K$4:$K$20,MATCH(H7,SpellData!$A$4:$A$20,0)),"")} -> FALSE | S7: {=IFERROR(INDEX(SpellData!$L$4:$L$20,MATCH(H7,SpellData!$A$4:$A$20,0)),"")} -> FALSE | T7: {=IFERROR(INDEX(SpellData!$M$4:$M$20,MATCH(H7,SpellData!$A$4:$A$20,0)),"")} -> Instant | U7: {=IFERROR(INDEX(SpellData!$N$4:$N$20,MATCH(H7,SpellData!$A$4:$A$20,0)),"")} -> Auto | V7: {=IFERROR(INDEX(SpellData!$O$4:$O$20,MATCH(H7,SpellData!$A$4:$A$20,0)),"")} | W7: {=IFERROR(INDEX(SpellData!$P$4:$P$20,MATCH(H7,SpellData!$A$4:$A$20,0)),"")} -> SlotDice | X7: {=IFERROR(INDEX(SpellData!$Q$4:$Q$20,MATCH(H7,SpellData!$A$4:$A$20,0)),"")} -> +1d6/slot | Y7: =IF(M7="Spell Attack",Character!$E$30,"") | Z7: =IF(N7="Spell DC",Character!$E$31,"") | AB7: {=IFERROR(INDEX(SpellData!$R$4:$R$20,MATCH(H7,SpellData!$A$4:$A$20,0)),"")}
A8: 3 | B8: 0 | C8: 0 | E8: TRUE | F8: FALSE | G8: TRUE | H8: Bless | I8: {=IFERROR(INDEX(SpellData!$B$4:$B$20,MATCH(H8,SpellData!$A$4:$A$20,0)),"")} -> 1 | J8: {=IFERROR(INDEX(SpellData!$C$4:$C$20,MATCH(H8,SpellData!$A$4:$A$20,0)),"")} -> Enchantment | K8: {=IFERROR(INDEX(SpellData!$D$4:$D$20,MATCH(H8,SpellData!$A$4:$A$20,0)),"")} -> Action | L8: {=IFERROR(INDEX(SpellData!$E$4:$E$20,MATCH(H8,SpellData!$A$4:$A$20,0)),"")} -> Buff | M8: {=IFERROR(INDEX(SpellData!$F$4:$F$20,MATCH(H8,SpellData!$A$4:$A$20,0)),"")} | N8: {=IFERROR(INDEX(SpellData!$G$4:$G$20,MATCH(H8,SpellData!$A$4:$A$20,0)),"")} | O8: {=IFERROR(INDEX(SpellData!$H$4:$H$20,MATCH(H8,SpellData!$A$4:$A$20,0)),"")} | P8: {=IFERROR(INDEX(SpellData!$I$4:$I$20,MATCH(H8,SpellData!$A$4:$A$20,0)),"")} -> 1d4 | Q8: {=IFERROR(INDEX(SpellData!$J$4:$J$20,MATCH(H8,SpellData!$A$4:$A$20,0)),"")} -> Buff | R8: {=IFERROR(INDEX(SpellData!$K$4:$K$20,MATCH(H8,SpellData!$A$4:$A$20,0)),"")} -> TRUE | S8: {=IFERROR(INDEX(SpellData!$L$4:$L$20,MATCH(H8,SpellData!$A$4:$A$20,0)),"")} -> FALSE | T8: {=IFERROR(INDEX(SpellData!$M$4:$M$20,MATCH(H8,SpellData!$A$4:$A$20,0)),"")} -> 1 minute | U8: {=IFERROR(INDEX(SpellData!$N$4:$N$20,MATCH(H8,SpellData!$A$4:$A$20,0)),"")} -> Auto | V8: {=IFERROR(INDEX(SpellData!$O$4:$O$20,MATCH(H8,SpellData!$A$4:$A$20,0)),"")} | W8: {=IFERROR(INDEX(SpellData!$P$4:$P$20,MATCH(H8,SpellData!$A$4:$A$20,0)),"")} -> None | X8: {=IFERROR(INDEX(SpellData!$Q$4:$Q$20,MATCH(H8,SpellData!$A$4:$A$20,0)),"")} | Y8: =IF(M8="Spell Attack",Character!$E$30,"") | Z8: =IF(N8="Spell DC",Character!$E$31,"") | AB8: {=IFERROR(INDEX(SpellData!$R$4:$R$20,MATCH(H8,SpellData!$A$4:$A$20,0)),"")} -> Add 1d4 to attacks and saves
A9: 4 | B9: 0 | C9: 0 | I9: {=IFERROR(INDEX(SpellData!$B$4:$B$20,MATCH(H9,SpellData!$A$4:$A$20,0)),"")} | J9: {=IFERROR(INDEX(SpellData!$C$4:$C$20,MATCH(H9,SpellData!$A$4:$A$20,0)),"")} | K9: {=IFERROR(INDEX(SpellData!$D$4:$D$20,MATCH(H9,SpellData!$A$4:$A$20,0)),"")} | L9: {=IFERROR(INDEX(SpellData!$E$4:$E$20,MATCH(H9,SpellData!$A$4:$A$20,0)),"")} | M9: {=IFERROR(INDEX(SpellData!$F$4:$F$20,MATCH(H9,SpellData!$A$4:$A$20,0)),"")} | N9: {=IFERROR(INDEX(SpellData!$G$4:$G$20,MATCH(H9,SpellData!$A$4:$A$20,0)),"")} | O9: {=IFERROR(INDEX(SpellData!$H$4:$H$20,MATCH(H9,SpellData!$A$4:$A$20,0)),"")} | P9: {=IFERROR(INDEX(SpellData!$I$4:$I$20,MATCH(H9,SpellData!$A$4:$A$20,0)),"")} | Q9: {=IFERROR(INDEX(SpellData!$J$4:$J$20,MATCH(H9,SpellData!$A$4:$A$20,0)),"")} | R9: {=IFERROR(INDEX(SpellData!$K$4:$K$20,MATCH(H9,SpellData!$A$4:$A$20,0)),"")} | S9: {=IFERROR(INDEX(SpellData!$L$4:$L$20,MATCH(H9,SpellData!$A$4:$A$20,0)),"")} | T9: {=IFERROR(INDEX(SpellData!$M$4:$M$20,MATCH(H9,SpellData!$A$4:$A$20,0)),"")} | U9: {=IFERROR(INDEX(SpellData!$N$4:$N$20,MATCH(H9,SpellData!$A$4:$A$20,0)),"")} | V9: {=IFERROR(INDEX(SpellData!$O$4:$O$20,MATCH(H9,SpellData!$A$4:$A$20,0)),"")} | W9: {=IFERROR(INDEX(SpellData!$P$4:$P$20,MATCH(H9,SpellData!$A$4:$A$20,0)),"")} | X9: {=IFERROR(INDEX(SpellData!$Q$4:$Q$20,MATCH(H9,SpellData!$A$4:$A$20,0)),"")} | Y9: =IF(M9="Spell Attack",Character!$E$30,"") | Z9: =IF(N9="Spell DC",Character!$E$31,"") | AB9: {=IFERROR(INDEX(SpellData!$R$4:$R$20,MATCH(H9,SpellData!$A$4:$A$20,0)),"")}
A10: 5 | B10: 0 | C10: 0 | I10: {=IFERROR(INDEX(SpellData!$B$4:$B$20,MATCH(H10,SpellData!$A$4:$A$20,0)),"")} | J10: {=IFERROR(INDEX(SpellData!$C$4:$C$20,MATCH(H10,SpellData!$A$4:$A$20,0)),"")} | K10: {=IFERROR(INDEX(SpellData!$D$4:$D$20,MATCH(H10,SpellData!$A$4:$A$20,0)),"")} | L10: {=IFERROR(INDEX(SpellData!$E$4:$E$20,MATCH(H10,SpellData!$A$4:$A$20,0)),"")} | M10: {=IFERROR(INDEX(SpellData!$F$4:$F$20,MATCH(H10,SpellData!$A$4:$A$20,0)),"")} | N10: {=IFERROR(INDEX(SpellData!$G$4:$G$20,MATCH(H10,SpellData!$A$4:$A$20,0)),"")} | O10: {=IFERROR(INDEX(SpellData!$H$4:$H$20,MATCH(H10,SpellData!$A$4:$A$20,0)),"")} | P10: {=IFERROR(INDEX(SpellData!$I$4:$I$20,MATCH(H10,SpellData!$A$4:$A$20,0)),"")} | Q10: {=IFERROR(INDEX(SpellData!$J$4:$J$20,MATCH(H10,SpellData!$A$4:$A$20,0)),"")} | R10: {=IFERROR(INDEX(SpellData!$K$4:$K$20,MATCH(H10,SpellData!$A$4:$A$20,0)),"")} | S10: {=IFERROR(INDEX(SpellData!$L$4:$L$20,MATCH(H10,SpellData!$A$4:$A$20,0)),"")} | T10: {=IFERROR(INDEX(SpellData!$M$4:$M$20,MATCH(H10,SpellData!$A$4:$A$20,0)),"")} | U10: {=IFERROR(INDEX(SpellData!$N$4:$N$20,MATCH(H10,SpellData!$A$4:$A$20,0)),"")} | V10: {=IFERROR(INDEX(SpellData!$O$4:$O$20,MATCH(H10,SpellData!$A$4:$A$20,0)),"")} | W10: {=IFERROR(INDEX(SpellData!$P$4:$P$20,MATCH(H10,SpellData!$A$4:$A$20,0)),"")} | X10: {=IFERROR(INDEX(SpellData!$Q$4:$Q$20,MATCH(H10,SpellData!$A$4:$A$20,0)),"")} | Y10: =IF(M10="Spell Attack",Character!$E$30,"") | Z10: =IF(N10="Spell DC",Character!$E$31,"") | AB10: {=IFERROR(INDEX(SpellData!$R$4:$R$20,MATCH(H10,SpellData!$A$4:$A$20,0)),"")}
A11: 6 | B11: 0 | C11: 0 | I11: {=IFERROR(INDEX(SpellData!$B$4:$B$20,MATCH(H11,SpellData!$A$4:$A$20,0)),"")} | J11: {=IFERROR(INDEX(SpellData!$C$4:$C$20,MATCH(H11,SpellData!$A$4:$A$20,0)),"")} | K11: {=IFERROR(INDEX(SpellData!$D$4:$D$20,MATCH(H11,SpellData!$A$4:$A$20,0)),"")} | L11: {=IFERROR(INDEX(SpellData!$E$4:$E$20,MATCH(H11,SpellData!$A$4:$A$20,0)),"")} | M11: {=IFERROR(INDEX(SpellData!$F$4:$F$20,MATCH(H11,SpellData!$A$4:$A$20,0)),"")} | N11: {=IFERROR(INDEX(SpellData!$G$4:$G$20,MATCH(H11,SpellData!$A$4:$A$20,0)),"")} | O11: {=IFERROR(INDEX(SpellData!$H$4:$H$20,MATCH(H11,SpellData!$A$4:$A$20,0)),"")} | P11: {=IFERROR(INDEX(SpellData!$I$4:$I$20,MATCH(H11,SpellData!$A$4:$A$20,0)),"")} | Q11: {=IFERROR(INDEX(SpellData!$J$4:$J$20,MATCH(H11,SpellData!$A$4:$A$20,0)),"")} | R11: {=IFERROR(INDEX(SpellData!$K$4:$K$20,MATCH(H11,SpellData!$A$4:$A$20,0)),"")} | S11: {=IFERROR(INDEX(SpellData!$L$4:$L$20,MATCH(H11,SpellData!$A$4:$A$20,0)),"")} | T11: {=IFERROR(INDEX(SpellData!$M$4:$M$20,MATCH(H11,SpellData!$A$4:$A$20,0)),"")} | U11: {=IFERROR(INDEX(SpellData!$N$4:$N$20,MATCH(H11,SpellData!$A$4:$A$20,0)),"")} | V11: {=IFERROR(INDEX(SpellData!$O$4:$O$20,MATCH(H11,SpellData!$A$4:$A$20,0)),"")} | W11: {=IFERROR(INDEX(SpellData!$P$4:$P$20,MATCH(H11,SpellData!$A$4:$A$20,0)),"")} | X11: {=IFERROR(INDEX(SpellData!$Q$4:$Q$20,MATCH(H11,SpellData!$A$4:$A$20,0)),"")} | Y11: =IF(M11="Spell Attack",Character!$E$30,"") | Z11: =IF(N11="Spell DC",Character!$E$31,"") | AB11: {=IFERROR(INDEX(SpellData!$R$4:$R$20,MATCH(H11,SpellData!$A$4:$A$20,0)),"")}
A12: 7 | B12: 0 | C12: 0 | I12: {=IFERROR(INDEX(SpellData!$B$4:$B$20,MATCH(H12,SpellData!$A$4:$A$20,0)),"")} | J12: {=IFERROR(INDEX(SpellData!$C$4:$C$20,MATCH(H12,SpellData!$A$4:$A$20,0)),"")} | K12: {=IFERROR(INDEX(SpellData!$D$4:$D$20,MATCH(H12,SpellData!$A$4:$A$20,0)),"")} | L12: {=IFERROR(INDEX(SpellData!$E$4:$E$20,MATCH(H12,SpellData!$A$4:$A$20,0)),"")} | M12: {=IFERROR(INDEX(SpellData!$F$4:$F$20,MATCH(H12,SpellData!$A$4:$A$20,0)),"")} | N12: {=IFERROR(INDEX(SpellData!$G$4:$G$20,MATCH(H12,SpellData!$A$4:$A$20,0)),"")} | O12: {=IFERROR(INDEX(SpellData!$H$4:$H$20,MATCH(H12,SpellData!$A$4:$A$20,0)),"")} | P12: {=IFERROR(INDEX(SpellData!$I$4:$I$20,MATCH(H12,SpellData!$A$4:$A$20,0)),"")} | Q12: {=IFERROR(INDEX(SpellData!$J$4:$J$20,MATCH(H12,SpellData!$A$4:$A$20,0)),"")} | R12: {=IFERROR(INDEX(SpellData!$K$4:$K$20,MATCH(H12,SpellData!$A$4:$A$20,0)),"")} | S12: {=IFERROR(INDEX(SpellData!$L$4:$L$20,MATCH(H12,SpellData!$A$4:$A$20,0)),"")} | T12: {=IFERROR(INDEX(SpellData!$M$4:$M$20,MATCH(H12,SpellData!$A$4:$A$20,0)),"")} | U12: {=IFERROR(INDEX(SpellData!$N$4:$N$20,MATCH(H12,SpellData!$A$4:$A$20,0)),"")} | V12: {=IFERROR(INDEX(SpellData!$O$4:$O$20,MATCH(H12,SpellData!$A$4:$A$20,0)),"")} | W12: {=IFERROR(INDEX(SpellData!$P$4:$P$20,MATCH(H12,SpellData!$A$4:$A$20,0)),"")} | X12: {=IFERROR(INDEX(SpellData!$Q$4:$Q$20,MATCH(H12,SpellData!$A$4:$A$20,0)),"")} | Y12: =IF(M12="Spell Attack",Character!$E$30,"") | Z12: =IF(N12="Spell DC",Character!$E$31,"") | AB12: {=IFERROR(INDEX(SpellData!$R$4:$R$20,MATCH(H12,SpellData!$A$4:$A$20,0)),"")}
A13: 8 | B13: 0 | C13: 0 | I13: {=IFERROR(INDEX(SpellData!$B$4:$B$20,MATCH(H13,SpellData!$A$4:$A$20,0)),"")} | J13: {=IFERROR(INDEX(SpellData!$C$4:$C$20,MATCH(H13,SpellData!$A$4:$A$20,0)),"")} | K13: {=IFERROR(INDEX(SpellData!$D$4:$D$20,MATCH(H13,SpellData!$A$4:$A$20,0)),"")} | L13: {=IFERROR(INDEX(SpellData!$E$4:$E$20,MATCH(H13,SpellData!$A$4:$A$20,0)),"")} | M13: {=IFERROR(INDEX(SpellData!$F$4:$F$20,MATCH(H13,SpellData!$A$4:$A$20,0)),"")} | N13: {=IFERROR(INDEX(SpellData!$G$4:$G$20,MATCH(H13,SpellData!$A$4:$A$20,0)),"")} | O13: {=IFERROR(INDEX(SpellData!$H$4:$H$20,MATCH(H13,SpellData!$A$4:$A$20,0)),"")} | P13: {=IFERROR(INDEX(SpellData!$I$4:$I$20,MATCH(H13,SpellData!$A$4:$A$20,0)),"")} | Q13: {=IFERROR(INDEX(SpellData!$J$4:$J$20,MATCH(H13,SpellData!$A$4:$A$20,0)),"")} | R13: {=IFERROR(INDEX(SpellData!$K$4:$K$20,MATCH(H13,SpellData!$A$4:$A$20,0)),"")} | S13: {=IFERROR(INDEX(SpellData!$L$4:$L$20,MATCH(H13,SpellData!$A$4:$A$20,0)),"")} | T13: {=IFERROR(INDEX(SpellData!$M$4:$M$20,MATCH(H13,SpellData!$A$4:$A$20,0)),"")} | U13: {=IFERROR(INDEX(SpellData!$N$4:$N$20,MATCH(H13,SpellData!$A$4:$A$20,0)),"")} | V13: {=IFERROR(INDEX(SpellData!$O$4:$O$20,MATCH(H13,SpellData!$A$4:$A$20,0)),"")} | W13: {=IFERROR(INDEX(SpellData!$P$4:$P$20,MATCH(H13,SpellData!$A$4:$A$20,0)),"")} | X13: {=IFERROR(INDEX(SpellData!$Q$4:$Q$20,MATCH(H13,SpellData!$A$4:$A$20,0)),"")} | Y13: =IF(M13="Spell Attack",Character!$E$30,"") | Z13: =IF(N13="Spell DC",Character!$E$31,"") | AB13: {=IFERROR(INDEX(SpellData!$R$4:$R$20,MATCH(H13,SpellData!$A$4:$A$20,0)),"")}
A14: 9 | B14: 0 | C14: 0 | I14: {=IFERROR(INDEX(SpellData!$B$4:$B$20,MATCH(H14,SpellData!$A$4:$A$20,0)),"")} | J14: {=IFERROR(INDEX(SpellData!$C$4:$C$20,MATCH(H14,SpellData!$A$4:$A$20,0)),"")} | K14: {=IFERROR(INDEX(SpellData!$D$4:$D$20,MATCH(H14,SpellData!$A$4:$A$20,0)),"")} | L14: {=IFERROR(INDEX(SpellData!$E$4:$E$20,MATCH(H14,SpellData!$A$4:$A$20,0)),"")} | M14: {=IFERROR(INDEX(SpellData!$F$4:$F$20,MATCH(H14,SpellData!$A$4:$A$20,0)),"")} | N14: {=IFERROR(INDEX(SpellData!$G$4:$G$20,MATCH(H14,SpellData!$A$4:$A$20,0)),"")} | O14: {=IFERROR(INDEX(SpellData!$H$4:$H$20,MATCH(H14,SpellData!$A$4:$A$20,0)),"")} | P14: {=IFERROR(INDEX(SpellData!$I$4:$I$20,MATCH(H14,SpellData!$A$4:$A$20,0)),"")} | Q14: {=IFERROR(INDEX(SpellData!$J$4:$J$20,MATCH(H14,SpellData!$A$4:$A$20,0)),"")} | R14: {=IFERROR(INDEX(SpellData!$K$4:$K$20,MATCH(H14,SpellData!$A$4:$A$20,0)),"")} | S14: {=IFERROR(INDEX(SpellData!$L$4:$L$20,MATCH(H14,SpellData!$A$4:$A$20,0)),"")} | T14: {=IFERROR(INDEX(SpellData!$M$4:$M$20,MATCH(H14,SpellData!$A$4:$A$20,0)),"")} | U14: {=IFERROR(INDEX(SpellData!$N$4:$N$20,MATCH(H14,SpellData!$A$4:$A$20,0)),"")} | V14: {=IFERROR(INDEX(SpellData!$O$4:$O$20,MATCH(H14,SpellData!$A$4:$A$20,0)),"")} | W14: {=IFERROR(INDEX(SpellData!$P$4:$P$20,MATCH(H14,SpellData!$A$4:$A$20,0)),"")} | X14: {=IFERROR(INDEX(SpellData!$Q$4:$Q$20,MATCH(H14,SpellData!$A$4:$A$20,0)),"")} | Y14: =IF(M14="Spell Attack",Character!$E$30,"") | Z14: =IF(N14="Spell DC",Character!$E$31,"") | AB14: {=IFERROR(INDEX(SpellData!$R$4:$R$20,MATCH(H14,SpellData!$A$4:$A$20,0)),"")}
I15: {=IFERROR(INDEX(SpellData!$B$4:$B$20,MATCH(H15,SpellData!$A$4:$A$20,0)),"")} | J15: {=IFERROR(INDEX(SpellData!$C$4:$C$20,MATCH(H15,SpellData!$A$4:$A$20,0)),"")} | K15: {=IFERROR(INDEX(SpellData!$D$4:$D$20,MATCH(H15,SpellData!$A$4:$A$20,0)),"")} | L15: {=IFERROR(INDEX(SpellData!$E$4:$E$20,MATCH(H15,SpellData!$A$4:$A$20,0)),"")} | M15: {=IFERROR(INDEX(SpellData!$F$4:$F$20,MATCH(H15,SpellData!$A$4:$A$20,0)),"")} | N15: {=IFERROR(INDEX(SpellData!$G$4:$G$20,MATCH(H15,SpellData!$A$4:$A$20,0)),"")} | O15: {=IFERROR(INDEX(SpellData!$H$4:$H$20,MATCH(H15,SpellData!$A$4:$A$20,0)),"")} | P15: {=IFERROR(INDEX(SpellData!$I$4:$I$20,MATCH(H15,SpellData!$A$4:$A$20,0)),"")} | Q15: {=IFERROR(INDEX(SpellData!$J$4:$J$20,MATCH(H15,SpellData!$A$4:$A$20,0)),"")} | R15: {=IFERROR(INDEX(SpellData!$K$4:$K$20,MATCH(H15,SpellData!$A$4:$A$20,0)),"")} | S15: {=IFERROR(INDEX(SpellData!$L$4:$L$20,MATCH(H15,SpellData!$A$4:$A$20,0)),"")} | T15: {=IFERROR(INDEX(SpellData!$M$4:$M$20,MATCH(H15,SpellData!$A$4:$A$20,0)),"")} | U15: {=IFERROR(INDEX(SpellData!$N$4:$N$20,MATCH(H15,SpellData!$A$4:$A$20,0)),"")} | V15: {=IFERROR(INDEX(SpellData!$O$4:$O$20,MATCH(H15,SpellData!$A$4:$A$20,0)),"")} | W15: {=IFERROR(INDEX(SpellData!$P$4:$P$20,MATCH(H15,SpellData!$A$4:$A$20,0)),"")} | X15: {=IFERROR(INDEX(SpellData!$Q$4:$Q$20,MATCH(H15,SpellData!$A$4:$A$20,0)),"")} | Y15: =IF(M15="Spell Attack",Character!$E$30,"") | Z15: =IF(N15="Spell DC",Character!$E$31,"") | AB15: {=IFERROR(INDEX(SpellData!$R$4:$R$20,MATCH(H15,SpellData!$A$4:$A$20,0)),"")}
I16: {=IFERROR(INDEX(SpellData!$B$4:$B$20,MATCH(H16,SpellData!$A$4:$A$20,0)),"")} | J16: {=IFERROR(INDEX(SpellData!$C$4:$C$20,MATCH(H16,SpellData!$A$4:$A$20,0)),"")} | K16: {=IFERROR(INDEX(SpellData!$D$4:$D$20,MATCH(H16,SpellData!$A$4:$A$20,0)),"")} | L16: {=IFERROR(INDEX(SpellData!$E$4:$E$20,MATCH(H16,SpellData!$A$4:$A$20,0)),"")} | M16: {=IFERROR(INDEX(SpellData!$F$4:$F$20,MATCH(H16,SpellData!$A$4:$A$20,0)),"")} | N16: {=IFERROR(INDEX(SpellData!$G$4:$G$20,MATCH(H16,SpellData!$A$4:$A$20,0)),"")} | O16: {=IFERROR(INDEX(SpellData!$H$4:$H$20,MATCH(H16,SpellData!$A$4:$A$20,0)),"")} | P16: {=IFERROR(INDEX(SpellData!$I$4:$I$20,MATCH(H16,SpellData!$A$4:$A$20,0)),"")} | Q16: {=IFERROR(INDEX(SpellData!$J$4:$J$20,MATCH(H16,SpellData!$A$4:$A$20,0)),"")} | R16: {=IFERROR(INDEX(SpellData!$K$4:$K$20,MATCH(H16,SpellData!$A$4:$A$20,0)),"")} | S16: {=IFERROR(INDEX(SpellData!$L$4:$L$20,MATCH(H16,SpellData!$A$4:$A$20,0)),"")} | T16: {=IFERROR(INDEX(SpellData!$M$4:$M$20,MATCH(H16,SpellData!$A$4:$A$20,0)),"")} | U16: {=IFERROR(INDEX(SpellData!$N$4:$N$20,MATCH(H16,SpellData!$A$4:$A$20,0)),"")} | V16: {=IFERROR(INDEX(SpellData!$O$4:$O$20,MATCH(H16,SpellData!$A$4:$A$20,0)),"")} | W16: {=IFERROR(INDEX(SpellData!$P$4:$P$20,MATCH(H16,SpellData!$A$4:$A$20,0)),"")} | X16: {=IFERROR(INDEX(SpellData!$Q$4:$Q$20,MATCH(H16,SpellData!$A$4:$A$20,0)),"")} | Y16: =IF(M16="Spell Attack",Character!$E$30,"") | Z16: =IF(N16="Spell DC",Character!$E$31,"") | AB16: {=IFERROR(INDEX(SpellData!$R$4:$R$20,MATCH(H16,SpellData!$A$4:$A$20,0)),"")}
